<?xml version='1.0'?>

<robot name="myrobot" xmlns:xacro="http://www.ros.org/wiki/xacro">

  
  
  <!-- <xacro:include filename="$(find description_my_robot)/urdf/materials.xacro"/> -->
  <xacro:include filename="$(find description_my_robot)/urdf/spcbot.gazebo"/>


  <!-- مواد الروبوت -->
  <material name="black">
    <color rgba="0.0 0.0 0.0 1.0"/>
  </material>

  <material name="yellow">
    <color rgba="1.0 1.0 0.0 1.0"/>
  </material>

  <material name="gray">
    <color rgba="0.5 0.5 0.5 1.0"/>
  </material>
  <!--_______________________________________________________________chassis____________________________________________________________________ -->

  <link name='chassis'>
    
    <collision name='collision'>
      <geometry>
        <box size=".4 .2 .1"/>
      </geometry>
    </collision>

    <visual name='chassis_visual'>
      <origin xyz="0 0 0" rpy=" 0 0 0"/>
      <geometry>
        <box size=".4 .2 .1"/>
      </geometry>
      <material name="black"/>
    </visual>

    <inertial>
      <origin xyz="0 0 0" rpy="0 0 0"/>
      <mass value="1.3729096e+00"/>
      <inertia ixx="8.7002718e-03" ixy="-4.7576583e-05" ixz="1.1160499e-04"
               iyy="8.6195418e-03" iyz="-3.5422299e-06"
               izz="1.4612727e-02" />
    </inertial>

    <collision name='caster_collision'>
      <origin xyz="-0.15 0 -0.05" rpy=" 0 0 0"/>
      <geometry>
        <sphere radius="0.05"/>
      </geometry>
       <surface>
        <friction>
          <ode>
            <mu>0.1</mu>
            <mu2>0.1</mu2>
          </ode>
        </friction>
      </surface> 
    </collision>

    <visual name='caster_visual'>
      <origin xyz="-0.15 0 -0.05" rpy=" 0 0 0"/>
      <geometry>
        <sphere radius="0.05"/>
      </geometry>
    </visual>

    
  </link>


  <!--_______________________________________________________________ base_footprint ____________________________________________________________________ -->


  <link name="base_footprint"/>

  <joint name="base_joint" type="fixed">
    <parent link="base_footprint"/>
    <child link="chassis"/>
    <origin xyz="0 0 0.01" rpy=" 0 0 0"/>

  </joint>


  <!--_______________________________________________________________left_wheel____________________________________________________________________ -->



  <link name="left_wheel">
    <!--origin xyz="0.1 0.13 0.1" rpy="0 1.5707 1.5707"/-->
    
    <collision name="collision">
      <origin xyz="0 0 0" rpy="0 1.5707 1.5707"/>
      <geometry>
        <cylinder radius="0.1" length="0.05"/>
      </geometry>
    </collision>

    <visual name="left_wheel_visual">
      <origin xyz="0 0 0" rpy="0 1.5707 1.5707"/>
      <geometry>
        <cylinder radius="0.1" length="0.05"/>
      </geometry>
      <material name="yellow"/>
    </visual>

    <inertial>
      <origin xyz="0 0 0" rpy="0 1.5707 1.5707"/>
      <mass value="2.8498940e-02" />
      <inertia ixx="1.1175580e-05" ixy="-4.2369783e-11" ixz="-5.9381719e-09"
               iyy="1.1192413e-05" iyz="-1.4400107e-11"
               izz="2.0712558e-05" />
      </inertial>
  </link>

  <joint type="continuous" name="left_wheel_hinge">
    <origin xyz="0.1 0.175 0" rpy="0 0 0"/>
    <!--origin xyz="0.1 0.13 0" rpy="0 1.5707 1.5707"/-->
    <child link="left_wheel"/>
    <parent link="chassis"/>
    <axis xyz="0 1 0" rpy="0 0 0"/>
    <!--limit effort="100" velocity="100"/>-->
    <!-- <limit effort="10000" velocity="1000"/> -->
    <!--joint_properties damping="0.0" friction="0.0"/>-->
  </joint>

  <!--_______________________________________________________________right_wheel____________________________________________________________________ -->

  <link name="right_wheel">
    <!--origin xyz="0.1 -0.13 0.1" rpy="0 1.5707 1.5707"/-->
    <collision name="collision">
      <origin xyz="0 0 0" rpy="0 1.5707 1.5707"/>
      <geometry>
        <cylinder radius="0.1" length="0.05"/>
      </geometry>
    </collision>

    <visual name="right_wheel_visual">
      <origin xyz="0 0 0" rpy="0 1.5707 1.5707"/>
      <geometry>
        <cylinder radius="0.1" length="0.05"/>
      </geometry>
      <material name="yellow"/>
    </visual>

    <inertial>
      <origin xyz="0 0 0" rpy="0 1.5707 1.5707"/>
      <mass value="2.8498940e-02" />
      <inertia ixx="1.1175580e-05" ixy="-4.2369783e-11" ixz="-5.9381719e-09"
               iyy="1.1192413e-05" iyz="-1.4400107e-11"
               izz="2.0712558e-05" />
      </inertial>
  </link>


  <joint type="continuous" name="right_wheel_hinge">
    <origin xyz="0.1 -0.175 0" rpy="0 0 0"/>
    <!--origin xyz="0.1 -0.13 0" rpy="0 1.5707 1.5707"/-->
    <child link="right_wheel"/>
    <parent link="chassis"/>
    <axis xyz="0 1 0" rpy="0 0 0"/>
    <!--limit effort="100" velocity="100"/>-->
    <!-- <limit effort="10000" velocity="1000"/> -->
    <!--joint_properties damping="0.0" friction="0.0"/>-->
  </joint>

<!--_______________________________________________________________Hokuyo Laser____________________________________________________________________ -->

  <link name="hokuyo_link">
    <collision>
      <origin xyz="0 0 0.1" rpy="0 0 0"/>
      <geometry>
    <box size="0.1 0.1 0.1"/>
      </geometry>
    </collision>

    <visual>
      <origin xyz="0 0 0.1" rpy="0 0 0"/>
      <geometry>
        <mesh filename="package://turtlebot3_description/meshes/sensors/lds.stl" scale="0.001 0.001 0.001"/>
      </geometry>
      <material name="gray"/>
    </visual>

    <inertial>
      <mass value="0.114" />
      <origin xyz="0 0 0" rpy="0 0 0"/>
      <inertia ixx="0.001" ixy="0.0" ixz="0.0"
               iyy="0.001" iyz="0.0"
               izz="0.001" />
    </inertial>
  </link>

  <joint name="hokuyo_joint" type="fixed">
    <!--axis xyz="0 1 0" />-->
    <origin xyz="0.15 0 0.13" rpy="0 0 0"/>
    <parent link="chassis"/>
    <child link="hokuyo_link"/>
  </joint>  

  


</robot>